<sdf version='1.7'>
  <world name='default'>
    <light name='sun' type='directional'>
      <cast_shadows>0</cast_shadows>
      <pose>0 0 10 0 -0 0</pose>
      <diffuse>0.8 0.8 0.8 1</diffuse>
      <specular>0.1 0.1 0.1 1</specular>
      <attenuation>
        <range>1000</range>
        <constant>0.9</constant>
        <linear>0.01</linear>
        <quadratic>0.001</quadratic>
      </attenuation>
      <direction>-0.5 0.5 -1</direction>
      <spot>
        <inner_angle>0</inner_angle>
        <outer_angle>0</outer_angle>
        <falloff>0</falloff>
      </spot>
    </light>
    <model name='ground_plane'>
      <static>1</static>
      <link name='link'>
        <collision name='collision'>
          <geometry>
            <plane>
              <normal>0 0 1</normal>
              <size>100 100</size>
            </plane>
          </geometry>
          <surface>
            <friction>
              <ode>
                <mu>100</mu>
                <mu2>50</mu2>
              </ode>
              <torsional>
                <ode/>
              </torsional>
            </friction>
            <contact>
              <ode/>
            </contact>
            <bounce/>
          </surface>
          <max_contacts>10</max_contacts>
        </collision>
        <visual name='visual'>
          <cast_shadows>0</cast_shadows>
          <geometry>
            <plane>
              <normal>0 0 1</normal>
              <size>100 100</size>
            </plane>
          </geometry>
          <material>
            <script>
              <uri>file://media/materials/scripts/gazebo.material</uri>
              <name>Gazebo/Grey</name>
            </script>
          </material>
        </visual>
        <self_collide>0</self_collide>
        <kinematic>0</kinematic>
        <gravity>1</gravity>
        <enable_wind>0</enable_wind>
      </link>
    </model>
    <gravity>0 0 -9.8</gravity>
    <magnetic_field>6e-06 2.3e-05 -4.2e-05</magnetic_field>
    <atmosphere type='adiabatic'/>
    <physics name='default_physics' default='0' type='ode'>
      <max_step_size>0.001</max_step_size>
      <real_time_factor>1</real_time_factor>
      <real_time_update_rate>1000</real_time_update_rate>
    </physics>
    <scene>
      <grid>1</grid>
      <ambient>0.4 0.4 0.4 1</ambient>
      <background>0.7 0.7 0.7 1</background>
      <shadows>1</shadows>
      <grid_size>100</grid_size>
    </scene>
    <spherical_coordinates>
      <surface_model>EARTH_WGS84</surface_model>
      <latitude_deg>0</latitude_deg>
      <longitude_deg>0</longitude_deg>
      <elevation>0</elevation>
      <heading_deg>0</heading_deg>
    </spherical_coordinates>
    <state world_name='default'>
      <sim_time>5566 585000000</sim_time>
      <real_time>82 304315209</real_time>
      <wall_time>1745930581 3905950</wall_time>
      <iterations>81214</iterations>
      <model name='grey_wall_1'>
        <pose>0 20 0 0 -0 0</pose>
        <scale>1 1 1</scale>
        <link name='link'>
          <pose>0 20 0 0 -0 0</pose>
          <velocity>0 0 0 0 -0 0</velocity>
          <acceleration>0 0 0 0 -0 0</acceleration>
          <wrench>0 0 0 0 -0 0</wrench>
        </link>
      </model>
      <model name='grey_wall_2'>
        <pose>0 -20 0 0 -0 0</pose>
        <scale>1 1 1</scale>
        <link name='link'>
          <pose>0 -20 0 0 -0 0</pose>
          <velocity>0 0 0 0 -0 0</velocity>
          <acceleration>0 0 0 0 -0 0</acceleration>
          <wrench>0 0 0 0 -0 0</wrench>
        </link>
      </model>
      <model name='grey_wall_3'>
        <pose>-20 0 0 0 -0 1.5708</pose>
        <scale>1 1 1</scale>
        <link name='link'>
          <pose>-20 0 0 0 -0 1.5708</pose>
          <velocity>0 0 0 0 -0 0</velocity>
          <acceleration>0 0 0 0 -0 0</acceleration>
          <wrench>0 0 0 0 -0 0</wrench>
        </link>
      </model>
      <model name='grey_wall_4'>
        <pose>20 0 0 0 -0 1.5708</pose>
        <scale>1 1 1</scale>
        <link name='link'>
          <pose>20 0 0 0 -0 1.5708</pose>
          <velocity>0 0 0 0 -0 0</velocity>
          <acceleration>0 0 0 0 -0 0</acceleration>
          <wrench>0 0 0 0 -0 0</wrench>
        </link>
      </model>
      <model name='ground_plane'>
        <pose>0 0 0 0 -0 0</pose>
        <scale>1 1 1</scale>
        <link name='link'>
          <pose>0 0 0 0 -0 0</pose>
          <velocity>0 0 0 0 -0 0</velocity>
          <acceleration>0 0 0 0 -0 0</acceleration>
          <wrench>0 0 0 0 -0 0</wrench>
        </link>
      </model>
      <model name='suv_clone_0_clone_6_clone'>
        <pose>-9.43085 7.30444 0 0 -0 0</pose>
        <scale>1 1 1</scale>
        <link name='link'>
          <pose>-9.43085 7.30444 0 0 -0 0</pose>
          <velocity>0 0 0 0 -0 0</velocity>
          <acceleration>0 0 0 0 -0 0</acceleration>
          <wrench>0 0 0 0 -0 0</wrench>
        </link>
      </model>
      <model name='suv_clone_0_clone_6_clone_0'>
        <pose>-9.5684 -6.91919 0 0 -0 0</pose>
        <scale>1 1 1</scale>
        <link name='link'>
          <pose>-9.5684 -6.91919 0 0 -0 0</pose>
          <velocity>0 0 0 0 -0 0</velocity>
          <acceleration>0 0 0 0 -0 0</acceleration>
          <wrench>0 0 0 0 -0 0</wrench>
        </link>
      </model>
      <model name='suv_clone_0_clone_9_clone_14'>
        <pose>15.2987 9.95565 -0.102894 0 -0 0.508668</pose>
        <scale>1 1 1</scale>
        <link name='link'>
          <pose>15.2987 9.95565 -0.102894 0 -0 0.508668</pose>
          <velocity>0 0 0 0 -0 0</velocity>
          <acceleration>0 0 0 0 -0 0</acceleration>
          <wrench>0 0 0 0 -0 0</wrench>
        </link>
      </model>
      <model name='suv_clone_0_clone_9_clone_4'>
        <pose>17.6237 -13.7333 0 0 -0 0</pose>
        <scale>1 1 1</scale>
        <link name='link'>
          <pose>17.6237 -13.7333 0 0 -0 0</pose>
          <velocity>0 0 0 0 -0 0</velocity>
          <acceleration>0 0 0 0 -0 0</acceleration>
          <wrench>0 0 0 0 -0 0</wrench>
        </link>
      </model>
      <model name='suv_clone_0_clone_9_clone_4_clone_1'>
        <pose>3.90465 6.79891 0 0 -0 0</pose>
        <scale>1 1 1</scale>
        <link name='link'>
          <pose>3.90465 6.79891 0 0 -0 0</pose>
          <velocity>0 0 0 0 -0 0</velocity>
          <acceleration>0 0 0 0 -0 0</acceleration>
          <wrench>0 0 0 0 -0 0</wrench>
        </link>
      </model>
      <model name='suv_clone_0_clone_9_clone_4_clone_2'>
        <pose>3.90417 8.61402 0 0 -0 0</pose>
        <scale>1 1 1</scale>
        <link name='link'>
          <pose>3.90417 8.61402 0 0 -0 0</pose>
          <velocity>0 0 0 0 -0 0</velocity>
          <acceleration>0 0 0 0 -0 0</acceleration>
          <wrench>0 0 0 0 -0 0</wrench>
        </link>
      </model>
      <model name='suv_clone_0_clone_9_clone_4_clone_3'>
        <pose>4.02254 10.4838 0 0 -0 0</pose>
        <scale>1 1 1</scale>
        <link name='link'>
          <pose>4.02254 10.4838 0 0 -0 0</pose>
          <velocity>0 0 0 0 -0 0</velocity>
          <acceleration>0 0 0 0 -0 0</acceleration>
          <wrench>0 0 0 0 -0 0</wrench>
        </link>
      </model>
      <model name='suv_clone_0_clone_9_clone_4_clone_4'>
        <pose>3.96453 12.3301 0 0 -0 0</pose>
        <scale>1 1 1</scale>
        <link name='link'>
          <pose>3.96453 12.3301 0 0 -0 0</pose>
          <velocity>0 0 0 0 -0 0</velocity>
          <acceleration>0 0 0 0 -0 0</acceleration>
          <wrench>0 0 0 0 -0 0</wrench>
        </link>
      </model>
      <model name='suv_clone_0_clone_9_clone_4_clone_5'>
        <pose>3.96967 14.3206 0 0 -0 0</pose>
        <scale>1 1 1</scale>
        <link name='link'>
          <pose>3.96967 14.3206 0 0 -0 0</pose>
          <velocity>0 0 0 0 -0 0</velocity>
          <acceleration>0 0 0 0 -0 0</acceleration>
          <wrench>0 0 0 0 -0 0</wrench>
        </link>
      </model>
      <model name='suv_clone_0_clone_9_clone_4_clone_6'>
        <pose>4.09085 16.2783 0 0 -0 0</pose>
        <scale>1 1 1</scale>
        <link name='link'>
          <pose>4.09085 16.2783 0 0 -0 0</pose>
          <velocity>0 0 0 0 -0 0</velocity>
          <acceleration>0 0 0 0 -0 0</acceleration>
          <wrench>0 0 0 0 -0 0</wrench>
        </link>
      </model>
      <model name='suv_clone_0_clone_9_clone_4_clone_7'>
        <pose>4.03469 18.1829 0 0 -0 0</pose>
        <scale>1 1 1</scale>
        <link name='link'>
          <pose>4.03469 18.1829 0 0 -0 0</pose>
          <velocity>0 0 0 0 -0 0</velocity>
          <acceleration>0 0 0 0 -0 0</acceleration>
          <wrench>0 0 0 0 -0 0</wrench>
        </link>
      </model>
      <model name='suv_clone_0_clone_9_clone_5'>
        <pose>17.5518 -15.4596 0 0 -0 0</pose>
        <scale>1 1 1</scale>
        <link name='link'>
          <pose>17.5518 -15.4596 0 0 -0 0</pose>
          <velocity>0 0 0 0 -0 0</velocity>
          <acceleration>0 0 0 0 -0 0</acceleration>
          <wrench>0 0 0 0 -0 0</wrench>
        </link>
      </model>
      <model name='suv_clone_0_clone_9_clone_6'>
        <pose>17.5518 -17.186 0 0 -0 0</pose>
        <scale>1 1 1</scale>
        <link name='link'>
          <pose>17.5518 -17.186 0 0 -0 0</pose>
          <velocity>0 0 0 0 -0 0</velocity>
          <acceleration>0 0 0 0 -0 0</acceleration>
          <wrench>0 0 0 0 -0 0</wrench>
        </link>
      </model>
      <model name='suv_clone_0_clone_9_clone_7'>
        <pose>17.6597 -18.9483 0 0 -0 0</pose>
        <scale>1 1 1</scale>
        <link name='link'>
          <pose>17.6597 -18.9483 0 0 -0 0</pose>
          <velocity>0 0 0 0 -0 0</velocity>
          <acceleration>0 0 0 0 -0 0</acceleration>
          <wrench>0 0 0 0 -0 0</wrench>
        </link>
      </model>
      <model name='swerve_drive_robot'>
        <pose>9.0818 9.92361 2.54129 -0.011667 0.002775 0.104777</pose>
        <scale>1 1 1</scale>
        <link name='base_link'>
          <pose>9.0818 9.92361 2.54129 -0.011667 0.002775 0.104777</pose>
          <velocity>-0.001504 -0.000349 0.000222 -0.002999 -0.000407 -0.001457</velocity>
          <acceleration>0.196593 0.085135 0.027346 0.03339 -0.0678 -0.04168</acceleration>
          <wrench>0.216252 0.093649 0.03008 0 -0 0</wrench>
        </link>
        <link name='front_left_steering_link'>
          <pose>11.7604 11.4609 2.41888 -0.011653 0.002764 0.104783</pose>
          <velocity>0.000657 -0.004605 -0.003038 -0.00525 0.00074 -0.001459</velocity>
          <acceleration>0.297269 -0.023813 0.253534 -0.014838 -0.042431 -0.052091</acceleration>
          <wrench>0.891806 -0.071439 0.760603 0 -0 0</wrench>
        </link>
        <link name='front_left_suspension_link'>
          <pose>11.7569 11.4349 0.257786 -0.011066 0.002294 0.104719</pose>
          <velocity>-0.031913 -0.066767 -0.117609 -0.106196 0.050498 0.011998</velocity>
          <acceleration>1.46429 2.76165 -0.272001 -1.92399 1.06055 0.097361</acceleration>
          <wrench>0.732147 1.38082 -0.136001 0 -0 0</wrench>
        </link>
        <link name='front_left_wheel_link'>
          <pose>11.7567 11.4326 0.055799 -3.13081 0.222404 -3.03518</pose>
          <velocity>-0.042645 -0.086508 -0.117403 -0.19981 0.041909 0.134689</velocity>
          <acceleration>1.24266 2.34379 -0.267695 1.26295 0.780295 -2.22254</acceleration>
          <wrench>0.621331 1.17189 -0.133847 0 -0 0</wrench>
        </link>
        <link name='front_right_steering_link'>
          <pose>12.0219 8.97482 2.44805 -0.011676 0.002777 0.104771</pose>
          <velocity>-0.002671 -0.004481 0.004225 -0.00209 -0.000477 -0.001745</velocity>
          <acceleration>0.198851 -0.09379 0.154889 -0.328102 -0.067698 -0.323459</acceleration>
          <wrench>0.596554 -0.281369 0.464666 0 -0 0</wrench>
        </link>
        <link name='front_right_suspension_link'>
          <pose>12.0186 8.94955 0.294351 -0.012043 0.002853 0.104757</pose>
          <velocity>0.002597 -0.019505 -0.123312 0.033859 -0.001077 -0.000484</velocity>
          <acceleration>-0.173234 -4.54849 -3.24245 -0.72618 0.001722 -2.01192</acceleration>
          <wrench>-0.086617 -2.27425 -1.62122 0 -0 0</wrench>
        </link>
        <link name='front_right_wheel_link'>
          <pose>12.0183 8.94707 0.092367 -0.077396 -1.40398 0.180878</pose>
          <velocity>0.00279 -0.012822 -0.123381 0.112377 0.024738 0.024185</velocity>
          <acceleration>-0.183413 -8.58079 -3.21275 -2.91105 -0.682955 -3.05929</acceleration>
          <wrench>-0.091707 -4.29039 -1.60637 0 -0 0</wrench>
        </link>
        <link name='rear_left_steering_link'>
          <pose>6.14138 10.87 2.43456 -0.011667 0.002781 0.104781</pose>
          <velocity>8.1e-05 0.003793 -0.003931 -0.002835 -0.000721 -0.001406</velocity>
          <acceleration>0.277199 0.23198 -0.145541 0.043953 -0.073017 -0.048618</acceleration>
          <wrench>0.831597 0.69594 -0.436624 0 -0 0</wrench>
        </link>
        <link name='rear_left_suspension_link'>
          <pose>6.13822 10.8444 0.282603 -0.011685 0.003026 0.104778</pose>
          <velocity>0.002571 -0.000202 -0.137773 0.00189 -0.011142 -0.00119</velocity>
          <acceleration>-0.42489 0.014972 -0.022087 0.022059 -0.254461 -0.056062</acceleration>
          <wrench>-0.212445 0.007486 -0.011044 0 -0 0</wrench>
        </link>
        <link name='rear_left_wheel_link'>
          <pose>6.13786 10.842 0.080617 -0.014181 0.600136 0.096799</pose>
          <velocity>0.004706 0.000149 -0.13778 -0.001197 0.046554 -2.8e-05</velocity>
          <acceleration>-0.37408 0.019852 -0.022304 3.08273 0.561993 2.86735</acceleration>
          <wrench>-0.18704 0.009926 -0.011152 0 -0 0</wrench>
        </link>
        <link name='rear_right_steering_link'>
          <pose>6.40291 8.38391 2.46373 -0.011666 0.002775 0.104777</pose>
          <velocity>-0.003648 0.003389 0.003571 -0.003002 -0.000424 -0.001448</velocity>
          <acceleration>0.169548 0.214951 -0.248692 0.043018 -0.077654 -0.051118</acceleration>
          <wrench>0.508645 0.644852 -0.746077 0 -0 0</wrench>
        </link>
        <link name='rear_right_suspension_link'>
          <pose>6.39957 8.35819 0.300791 -0.011691 0.002756 0.104777</pose>
          <velocity>-0.002787 -0.001399 -0.10979 0.000551 -0.001545 -0.001438</velocity>
          <acceleration>0.213871 0.148314 0.012112 -0.007502 0.281793 -0.044153</acceleration>
          <wrench>0.106936 0.074157 0.006056 0 -0 0</wrench>
        </link>
        <link name='rear_right_wheel_link'>
          <pose>6.39927 8.35578 0.098806 -0.025332 1.08861 0.082362</pose>
          <velocity>-0.002438 -0.001038 -0.109794 0.009206 -0.021161 -0.001059</velocity>
          <acceleration>0.114648 0.114941 0.012498 -1.00824 0.998397 -0.059598</acceleration>
          <wrench>0.057324 0.05747 0.006249 0 -0 0</wrench>
        </link>
      </model>
      <model name='unit_box_1'>
        <pose>-5.75705 -2.44272 0.499995 -1e-05 -0 -0</pose>
        <scale>1 1 1</scale>
        <link name='link'>
          <pose>-5.75705 -2.44272 0.499995 -1e-05 -0 -0</pose>
          <velocity>0 0 0 0 -0 0</velocity>
          <acceleration>0.004709 0.011055 -9.78158 -0.022108 0.009414 1e-06</acceleration>
          <wrench>0.004709 0.011055 -9.78158 0 -0 0</wrench>
        </link>
      </model>
      <model name='unit_box_2'>
        <pose>-5.62537 2.16547 0.5 0 -0 0</pose>
        <scale>1 1 1</scale>
        <link name='link'>
          <pose>-5.62537 2.16547 0.5 0 -0 0</pose>
          <velocity>0 0 0 0 -0 0</velocity>
          <acceleration>-0.004712 9.78112 9.78158 -0.712677 -0.00942 4.3e-05</acceleration>
          <wrench>-0.004712 9.78112 9.78158 0 -0 0</wrench>
        </link>
      </model>
      <model name='unit_box_3'>
        <pose>-5.75812 -3.94247 0.5 -0 -0 -0</pose>
        <scale>1 1 1</scale>
        <link name='link'>
          <pose>-5.75812 -3.94247 0.5 -0 -0 -0</pose>
          <velocity>0 0 0 0 -0 0</velocity>
          <acceleration>-0.004709 -9.78112 9.78158 0.712677 -0.009414 -4.3e-05</acceleration>
          <wrench>-0.004709 -9.78112 9.78158 0 -0 0</wrench>
        </link>
      </model>
      <light name='sun'>
        <pose>0 0 10 0 -0 0</pose>
      </light>
    </state>
    <model name='grey_wall_1'>
      <link name='link'>
        <pose>0 0 0 0 -0 0</pose>
        <self_collide>0</self_collide>
        <kinematic>0</kinematic>
        <gravity>1</gravity>
        <inertial>
          <mass>1</mass>
          <pose>0 0 0 0 -0 0</pose>
          <inertia>
            <ixx>1</ixx>
            <ixy>0</ixy>
            <ixz>0</ixz>
            <iyy>1</iyy>
            <iyz>0</iyz>
            <izz>1</izz>
          </inertia>
        </inertial>
        <visual name='visual'>
          <cast_shadows>0</cast_shadows>
          <geometry>
            <box>
              <size>40 0.2 2.8</size>
            </box>
          </geometry>
          <material>
            <script>
              <uri>model://grey_wall/materials/scripts</uri>
              <uri>model://grey_wall/materials/textures</uri>
              <name>vrc/grey_wall</name>
            </script>
            <ambient>1 1 1 1</ambient>
            <diffuse>1 1 1 1</diffuse>
            <specular>0 0 0 1</specular>
            <emissive>0 0 0 1</emissive>
            <shader type='vertex'>
              <normal_map>__default__</normal_map>
            </shader>
          </material>
          <pose>0 0 0 0 -0 0</pose>
          <transparency>0</transparency>
        </visual>
        <collision name='collision'>
          <laser_retro>0</laser_retro>
          <max_contacts>10</max_contacts>
          <pose>0 0 0 0 -0 0</pose>
          <geometry>
            <box>
              <size>40 0.2 2.8</size>
            </box>
          </geometry>
          <surface>
            <friction>
              <ode>
                <mu>1</mu>
                <mu2>1</mu2>
                <fdir1>0 0 0</fdir1>
                <slip1>0</slip1>
                <slip2>0</slip2>
              </ode>
              <torsional>
                <coefficient>1</coefficient>
                <patch_radius>0</patch_radius>
                <surface_radius>0</surface_radius>
                <use_patch_radius>1</use_patch_radius>
                <ode>
                  <slip>0</slip>
                </ode>
              </torsional>
            </friction>
            <bounce>
              <restitution_coefficient>0</restitution_coefficient>
              <threshold>1e+06</threshold>
            </bounce>
            <contact>
              <collide_without_contact>0</collide_without_contact>
              <collide_without_contact_bitmask>1</collide_without_contact_bitmask>
              <collide_bitmask>1</collide_bitmask>
              <ode>
                <soft_cfm>0</soft_cfm>
                <soft_erp>0.2</soft_erp>
                <kp>1e+13</kp>
                <kd>1</kd>
                <max_vel>0.01</max_vel>
                <min_depth>0</min_depth>
              </ode>
              <bullet>
                <split_impulse>1</split_impulse>
                <split_impulse_penetration_threshold>-0.01</split_impulse_penetration_threshold>
                <soft_cfm>0</soft_cfm>
                <soft_erp>0.2</soft_erp>
                <kp>1e+13</kp>
                <kd>1</kd>
              </bullet>
            </contact>
          </surface>
        </collision>
        <enable_wind>0</enable_wind>
      </link>
      <static>1</static>
      <allow_auto_disable>1</allow_auto_disable>
      <pose>2.68877 -9.29406 0 0 -0 0</pose>
    </model>
    <model name='grey_wall_2'>
      <link name='link'>
        <pose>0 0 0 0 -0 0</pose>
        <self_collide>0</self_collide>
        <kinematic>0</kinematic>
        <gravity>1</gravity>
        <inertial>
          <mass>1</mass>
          <pose>0 0 0 0 -0 0</pose>
          <inertia>
            <ixx>1</ixx>
            <ixy>0</ixy>
            <ixz>0</ixz>
            <iyy>1</iyy>
            <iyz>0</iyz>
            <izz>1</izz>
          </inertia>
        </inertial>
        <visual name='visual'>
          <cast_shadows>0</cast_shadows>
          <geometry>
            <box>
              <size>40 0.2 2.8</size>
            </box>
          </geometry>
          <material>
            <script>
              <uri>model://grey_wall/materials/scripts</uri>
              <uri>model://grey_wall/materials/textures</uri>
              <name>vrc/grey_wall</name>
            </script>
            <ambient>1 1 1 1</ambient>
            <diffuse>1 1 1 1</diffuse>
            <specular>0 0 0 1</specular>
            <emissive>0 0 0 1</emissive>
            <shader type='vertex'>
              <normal_map>__default__</normal_map>
            </shader>
          </material>
          <pose>0 0 0 0 -0 0</pose>
          <transparency>0</transparency>
        </visual>
        <collision name='collision'>
          <laser_retro>0</laser_retro>
          <max_contacts>10</max_contacts>
          <pose>0 0 0 0 -0 0</pose>
          <geometry>
            <box>
              <size>40 0.2 2.8</size>
            </box>
          </geometry>
          <surface>
            <friction>
              <ode>
                <mu>1</mu>
                <mu2>1</mu2>
                <fdir1>0 0 0</fdir1>
                <slip1>0</slip1>
                <slip2>0</slip2>
              </ode>
              <torsional>
                <coefficient>1</coefficient>
                <patch_radius>0</patch_radius>
                <surface_radius>0</surface_radius>
                <use_patch_radius>1</use_patch_radius>
                <ode>
                  <slip>0</slip>
                </ode>
              </torsional>
            </friction>
            <bounce>
              <restitution_coefficient>0</restitution_coefficient>
              <threshold>1e+06</threshold>
            </bounce>
            <contact>
              <collide_without_contact>0</collide_without_contact>
              <collide_without_contact_bitmask>1</collide_without_contact_bitmask>
              <collide_bitmask>1</collide_bitmask>
              <ode>
                <soft_cfm>0</soft_cfm>
                <soft_erp>0.2</soft_erp>
                <kp>1e+13</kp>
                <kd>1</kd>
                <max_vel>0.01</max_vel>
                <min_depth>0</min_depth>
              </ode>
              <bullet>
                <split_impulse>1</split_impulse>
                <split_impulse_penetration_threshold>-0.01</split_impulse_penetration_threshold>
                <soft_cfm>0</soft_cfm>
                <soft_erp>0.2</soft_erp>
                <kp>1e+13</kp>
                <kd>1</kd>
              </bullet>
            </contact>
          </surface>
        </collision>
        <enable_wind>0</enable_wind>
      </link>
      <static>1</static>
      <allow_auto_disable>1</allow_auto_disable>
      <pose>2.68877 -9.29406 0 0 -0 0</pose>
    </model>
    <model name='grey_wall_3'>
      <link name='link'>
        <pose>0 0 0 0 -0 0</pose>
        <self_collide>0</self_collide>
        <kinematic>0</kinematic>
        <gravity>1</gravity>
        <inertial>
          <mass>1</mass>
          <pose>0 0 0 0 -0 0</pose>
          <inertia>
            <ixx>1</ixx>
            <ixy>0</ixy>
            <ixz>0</ixz>
            <iyy>1</iyy>
            <iyz>0</iyz>
            <izz>1</izz>
          </inertia>
        </inertial>
        <visual name='visual'>
          <cast_shadows>0</cast_shadows>
          <geometry>
            <box>
              <size>40 0.2 2.8</size>
            </box>
          </geometry>
          <material>
            <script>
              <uri>model://grey_wall/materials/scripts</uri>
              <uri>model://grey_wall/materials/textures</uri>
              <name>vrc/grey_wall</name>
            </script>
            <ambient>1 1 1 1</ambient>
            <diffuse>1 1 1 1</diffuse>
            <specular>0 0 0 1</specular>
            <emissive>0 0 0 1</emissive>
            <shader type='vertex'>
              <normal_map>__default__</normal_map>
            </shader>
          </material>
          <pose>0 0 0 0 -0 0</pose>
          <transparency>0</transparency>
        </visual>
        <collision name='collision'>
          <laser_retro>0</laser_retro>
          <max_contacts>10</max_contacts>
          <pose>0 0 0 0 -0 0</pose>
          <geometry>
            <box>
              <size>40 0.2 2.8</size>
            </box>
          </geometry>
          <surface>
            <friction>
              <ode>
                <mu>1</mu>
                <mu2>1</mu2>
                <fdir1>0 0 0</fdir1>
                <slip1>0</slip1>
                <slip2>0</slip2>
              </ode>
              <torsional>
                <coefficient>1</coefficient>
                <patch_radius>0</patch_radius>
                <surface_radius>0</surface_radius>
                <use_patch_radius>1</use_patch_radius>
                <ode>
                  <slip>0</slip>
                </ode>
              </torsional>
            </friction>
            <bounce>
              <restitution_coefficient>0</restitution_coefficient>
              <threshold>1e+06</threshold>
            </bounce>
            <contact>
              <collide_without_contact>0</collide_without_contact>
              <collide_without_contact_bitmask>1</collide_without_contact_bitmask>
              <collide_bitmask>1</collide_bitmask>
              <ode>
                <soft_cfm>0</soft_cfm>
                <soft_erp>0.2</soft_erp>
                <kp>1e+13</kp>
                <kd>1</kd>
                <max_vel>0.01</max_vel>
                <min_depth>0</min_depth>
              </ode>
              <bullet>
                <split_impulse>1</split_impulse>
                <split_impulse_penetration_threshold>-0.01</split_impulse_penetration_threshold>
                <soft_cfm>0</soft_cfm>
                <soft_erp>0.2</soft_erp>
                <kp>1e+13</kp>
                <kd>1</kd>
              </bullet>
            </contact>
          </surface>
        </collision>
        <enable_wind>0</enable_wind>
      </link>
      <static>1</static>
      <allow_auto_disable>1</allow_auto_disable>
      <pose>2.68877 -9.29406 0 0 -0 0</pose>
    </model>
    <model name='grey_wall_4'>
      <link name='link'>
        <pose>0 0 0 0 -0 0</pose>
        <self_collide>0</self_collide>
        <kinematic>0</kinematic>
        <gravity>1</gravity>
        <inertial>
          <mass>1</mass>
          <pose>0 0 0 0 -0 0</pose>
          <inertia>
            <ixx>1</ixx>
            <ixy>0</ixy>
            <ixz>0</ixz>
            <iyy>1</iyy>
            <iyz>0</iyz>
            <izz>1</izz>
          </inertia>
        </inertial>
        <visual name='visual'>
          <cast_shadows>0</cast_shadows>
          <geometry>
            <box>
              <size>40 0.2 2.8</size>
            </box>
          </geometry>
          <material>
            <script>
              <uri>model://grey_wall/materials/scripts</uri>
              <uri>model://grey_wall/materials/textures</uri>
              <name>vrc/grey_wall</name>
            </script>
            <ambient>1 1 1 1</ambient>
            <diffuse>1 1 1 1</diffuse>
            <specular>0 0 0 1</specular>
            <emissive>0 0 0 1</emissive>
            <shader type='vertex'>
              <normal_map>__default__</normal_map>
            </shader>
          </material>
          <pose>0 0 0 0 -0 0</pose>
          <transparency>0</transparency>
        </visual>
        <collision name='collision'>
          <laser_retro>0</laser_retro>
          <max_contacts>10</max_contacts>
          <pose>0 0 0 0 -0 0</pose>
          <geometry>
            <box>
              <size>40 0.2 2.8</size>
            </box>
          </geometry>
          <surface>
            <friction>
              <ode>
                <mu>1</mu>
                <mu2>1</mu2>
                <fdir1>0 0 0</fdir1>
                <slip1>0</slip1>
                <slip2>0</slip2>
              </ode>
              <torsional>
                <coefficient>1</coefficient>
                <patch_radius>0</patch_radius>
                <surface_radius>0</surface_radius>
                <use_patch_radius>1</use_patch_radius>
                <ode>
                  <slip>0</slip>
                </ode>
              </torsional>
            </friction>
            <bounce>
              <restitution_coefficient>0</restitution_coefficient>
              <threshold>1e+06</threshold>
            </bounce>
            <contact>
              <collide_without_contact>0</collide_without_contact>
              <collide_without_contact_bitmask>1</collide_without_contact_bitmask>
              <collide_bitmask>1</collide_bitmask>
              <ode>
                <soft_cfm>0</soft_cfm>
                <soft_erp>0.2</soft_erp>
                <kp>1e+13</kp>
                <kd>1</kd>
                <max_vel>0.01</max_vel>
                <min_depth>0</min_depth>
              </ode>
              <bullet>
                <split_impulse>1</split_impulse>
                <split_impulse_penetration_threshold>-0.01</split_impulse_penetration_threshold>
                <soft_cfm>0</soft_cfm>
                <soft_erp>0.2</soft_erp>
                <kp>1e+13</kp>
                <kd>1</kd>
              </bullet>
            </contact>
          </surface>
        </collision>
        <enable_wind>0</enable_wind>
      </link>
      <static>1</static>
      <allow_auto_disable>1</allow_auto_disable>
      <pose>2.68877 -9.29406 0 0 -0 0</pose>
    </model>
    <gui fullscreen='0'>
      <camera name='user_camera'>
        <pose>3.13792 1.45437 22.1722 0 1.5258 1.7e-05</pose>
        <view_controller>orbit</view_controller>
        <projection_type>perspective</projection_type>
      </camera>
    </gui>
    <wind/>
    <model name='suv_clone_0_clone_9_clone_4'>
      <static>1</static>
      <link name='link'>
        <collision name='collision'>
          <pose>0 0 0 0 0 -1.5708</pose>
          <geometry>
            <mesh>
              <scale>0.04 0.04 0.04</scale>
              <uri>model://suv/meshes/suv.obj</uri>
            </mesh>
          </geometry>
          <max_contacts>10</max_contacts>
          <surface>
            <contact>
              <ode/>
            </contact>
            <bounce/>
            <friction>
              <torsional>
                <ode/>
              </torsional>
              <ode/>
            </friction>
          </surface>
        </collision>
        <visual name='visual'>
          <pose>0 0 0 0 0 -1.5708</pose>
          <geometry>
            <mesh>
              <scale>0.04 0.04 0.04</scale>
              <uri>model://suv/meshes/suv.obj</uri>
            </mesh>
          </geometry>
        </visual>
        <self_collide>0</self_collide>
        <kinematic>0</kinematic>
        <enable_wind>0</enable_wind>
      </link>
      <pose>17.6237 -13.7333 0 0 -0 0</pose>
    </model>
    <model name='suv_clone_0_clone_9_clone_5'>
      <static>1</static>
      <link name='link'>
        <collision name='collision'>
          <pose>0 0 0 0 0 -1.5708</pose>
          <geometry>
            <mesh>
              <scale>0.04 0.04 0.04</scale>
              <uri>model://suv/meshes/suv.obj</uri>
            </mesh>
          </geometry>
          <max_contacts>10</max_contacts>
          <surface>
            <contact>
              <ode/>
            </contact>
            <bounce/>
            <friction>
              <torsional>
                <ode/>
              </torsional>
              <ode/>
            </friction>
          </surface>
        </collision>
        <visual name='visual'>
          <pose>0 0 0 0 0 -1.5708</pose>
          <geometry>
            <mesh>
              <scale>0.04 0.04 0.04</scale>
              <uri>model://suv/meshes/suv.obj</uri>
            </mesh>
          </geometry>
        </visual>
        <self_collide>0</self_collide>
        <kinematic>0</kinematic>
        <enable_wind>0</enable_wind>
      </link>
      <pose>17.5518 -15.4596 0 0 -0 0</pose>
    </model>
    <model name='suv_clone_0_clone_9_clone_6'>
      <static>1</static>
      <link name='link'>
        <collision name='collision'>
          <pose>0 0 0 0 0 -1.5708</pose>
          <geometry>
            <mesh>
              <scale>0.04 0.04 0.04</scale>
              <uri>model://suv/meshes/suv.obj</uri>
            </mesh>
          </geometry>
          <max_contacts>10</max_contacts>
          <surface>
            <contact>
              <ode/>
            </contact>
            <bounce/>
            <friction>
              <torsional>
                <ode/>
              </torsional>
              <ode/>
            </friction>
          </surface>
        </collision>
        <visual name='visual'>
          <pose>0 0 0 0 0 -1.5708</pose>
          <geometry>
            <mesh>
              <scale>0.04 0.04 0.04</scale>
              <uri>model://suv/meshes/suv.obj</uri>
            </mesh>
          </geometry>
        </visual>
        <self_collide>0</self_collide>
        <kinematic>0</kinematic>
        <enable_wind>0</enable_wind>
      </link>
      <pose>17.5518 -17.186 0 0 -0 0</pose>
    </model>
    <model name='suv_clone_0_clone_9_clone_7'>
      <static>1</static>
      <link name='link'>
        <collision name='collision'>
          <pose>0 0 0 0 0 -1.5708</pose>
          <geometry>
            <mesh>
              <scale>0.04 0.04 0.04</scale>
              <uri>model://suv/meshes/suv.obj</uri>
            </mesh>
          </geometry>
          <max_contacts>10</max_contacts>
          <surface>
            <contact>
              <ode/>
            </contact>
            <bounce/>
            <friction>
              <torsional>
                <ode/>
              </torsional>
              <ode/>
            </friction>
          </surface>
        </collision>
        <visual name='visual'>
          <pose>0 0 0 0 0 -1.5708</pose>
          <geometry>
            <mesh>
              <scale>0.04 0.04 0.04</scale>
              <uri>model://suv/meshes/suv.obj</uri>
            </mesh>
          </geometry>
        </visual>
        <self_collide>0</self_collide>
        <kinematic>0</kinematic>
        <enable_wind>0</enable_wind>
      </link>
      <pose>17.6597 -18.9483 0 0 -0 0</pose>
    </model>
    <model name='suv_clone_0_clone_9_clone_14'>
      <static>1</static>
      <link name='link'>
        <collision name='collision'>
          <pose>0 0 0 0 0 -1.5708</pose>
          <geometry>
            <mesh>
              <scale>0.04 0.04 0.04</scale>
              <uri>model://suv/meshes/suv.obj</uri>
            </mesh>
          </geometry>
          <max_contacts>10</max_contacts>
          <surface>
            <contact>
              <ode/>
            </contact>
            <bounce/>
            <friction>
              <torsional>
                <ode/>
              </torsional>
              <ode/>
            </friction>
          </surface>
        </collision>
        <visual name='visual'>
          <pose>0 0 0 0 0 -1.5708</pose>
          <geometry>
            <mesh>
              <scale>0.04 0.04 0.04</scale>
              <uri>model://suv/meshes/suv.obj</uri>
            </mesh>
          </geometry>
        </visual>
        <self_collide>0</self_collide>
        <kinematic>0</kinematic>
        <enable_wind>0</enable_wind>
      </link>
      <pose>8 6 0 0 -0 0</pose>
    </model>
    <model name='suv_clone_0_clone_6_clone'>
      <static>1</static>
      <link name='link'>
        <collision name='collision'>
          <pose>0 0 0 0 0 -1.5708</pose>
          <geometry>
            <mesh>
              <scale>0.04 0.04 0.04</scale>
              <uri>model://suv/meshes/suv.obj</uri>
            </mesh>
          </geometry>
          <max_contacts>10</max_contacts>
          <surface>
            <contact>
              <ode/>
            </contact>
            <bounce/>
            <friction>
              <torsional>
                <ode/>
              </torsional>
              <ode/>
            </friction>
          </surface>
        </collision>
        <visual name='visual'>
          <pose>0 0 0 0 0 -1.5708</pose>
          <geometry>
            <mesh>
              <scale>0.04 0.04 0.04</scale>
              <uri>model://suv/meshes/suv.obj</uri>
            </mesh>
          </geometry>
        </visual>
        <self_collide>0</self_collide>
        <kinematic>0</kinematic>
        <enable_wind>0</enable_wind>
      </link>
      <pose>-9.43085 7.30444 0 0 -0 0</pose>
    </model>
    <model name='suv_clone_0_clone_6_clone_0'>
      <static>1</static>
      <link name='link'>
        <collision name='collision'>
          <pose>0 0 0 0 0 -1.5708</pose>
          <geometry>
            <mesh>
              <scale>0.04 0.04 0.04</scale>
              <uri>model://suv/meshes/suv.obj</uri>
            </mesh>
          </geometry>
          <max_contacts>10</max_contacts>
          <surface>
            <contact>
              <ode/>
            </contact>
            <bounce/>
            <friction>
              <torsional>
                <ode/>
              </torsional>
              <ode/>
            </friction>
          </surface>
        </collision>
        <visual name='visual'>
          <pose>0 0 0 0 0 -1.5708</pose>
          <geometry>
            <mesh>
              <scale>0.04 0.04 0.04</scale>
              <uri>model://suv/meshes/suv.obj</uri>
            </mesh>
          </geometry>
        </visual>
        <self_collide>0</self_collide>
        <kinematic>0</kinematic>
        <enable_wind>0</enable_wind>
      </link>
      <pose>-9.5684 -6.91919 0 0 -0 0</pose>
    </model>
    <model name='suv_clone_0_clone_9_clone_4_clone_1'>
      <static>1</static>
      <link name='link'>
        <collision name='collision'>
          <pose>0 0 0 0 0 -1.5708</pose>
          <geometry>
            <mesh>
              <scale>0.04 0.04 0.04</scale>
              <uri>model://suv/meshes/suv.obj</uri>
            </mesh>
          </geometry>
          <max_contacts>10</max_contacts>
          <surface>
            <contact>
              <ode/>
            </contact>
            <bounce/>
            <friction>
              <torsional>
                <ode/>
              </torsional>
              <ode/>
            </friction>
          </surface>
        </collision>
        <visual name='visual'>
          <pose>0 0 0 0 0 -1.5708</pose>
          <geometry>
            <mesh>
              <scale>0.04 0.04 0.04</scale>
              <uri>model://suv/meshes/suv.obj</uri>
            </mesh>
          </geometry>
        </visual>
        <self_collide>0</self_collide>
        <kinematic>0</kinematic>
        <enable_wind>0</enable_wind>
      </link>
      <pose>3.90465 6.79891 0 0 -0 0</pose>
    </model>
    <model name='suv_clone_0_clone_9_clone_4_clone_2'>
      <static>1</static>
      <link name='link'>
        <collision name='collision'>
          <pose>0 0 0 0 0 -1.5708</pose>
          <geometry>
            <mesh>
              <scale>0.04 0.04 0.04</scale>
              <uri>model://suv/meshes/suv.obj</uri>
            </mesh>
          </geometry>
          <max_contacts>10</max_contacts>
          <surface>
            <contact>
              <ode/>
            </contact>
            <bounce/>
            <friction>
              <torsional>
                <ode/>
              </torsional>
              <ode/>
            </friction>
          </surface>
        </collision>
        <visual name='visual'>
          <pose>0 0 0 0 0 -1.5708</pose>
          <geometry>
            <mesh>
              <scale>0.04 0.04 0.04</scale>
              <uri>model://suv/meshes/suv.obj</uri>
            </mesh>
          </geometry>
        </visual>
        <self_collide>0</self_collide>
        <kinematic>0</kinematic>
        <enable_wind>0</enable_wind>
      </link>
      <pose>3.90417 8.61402 0 0 -0 0</pose>
    </model>
    <model name='suv_clone_0_clone_9_clone_4_clone_3'>
      <static>1</static>
      <link name='link'>
        <collision name='collision'>
          <pose>0 0 0 0 0 -1.5708</pose>
          <geometry>
            <mesh>
              <scale>0.04 0.04 0.04</scale>
              <uri>model://suv/meshes/suv.obj</uri>
            </mesh>
          </geometry>
          <max_contacts>10</max_contacts>
          <surface>
            <contact>
              <ode/>
            </contact>
            <bounce/>
            <friction>
              <torsional>
                <ode/>
              </torsional>
              <ode/>
            </friction>
          </surface>
        </collision>
        <visual name='visual'>
          <pose>0 0 0 0 0 -1.5708</pose>
          <geometry>
            <mesh>
              <scale>0.04 0.04 0.04</scale>
              <uri>model://suv/meshes/suv.obj</uri>
            </mesh>
          </geometry>
        </visual>
        <self_collide>0</self_collide>
        <kinematic>0</kinematic>
        <enable_wind>0</enable_wind>
      </link>
      <pose>4.02254 10.4838 0 0 -0 0</pose>
    </model>
    <model name='suv_clone_0_clone_9_clone_4_clone_4'>
      <static>1</static>
      <link name='link'>
        <collision name='collision'>
          <pose>0 0 0 0 0 -1.5708</pose>
          <geometry>
            <mesh>
              <scale>0.04 0.04 0.04</scale>
              <uri>model://suv/meshes/suv.obj</uri>
            </mesh>
          </geometry>
          <max_contacts>10</max_contacts>
          <surface>
            <contact>
              <ode/>
            </contact>
            <bounce/>
            <friction>
              <torsional>
                <ode/>
              </torsional>
              <ode/>
            </friction>
          </surface>
        </collision>
        <visual name='visual'>
          <pose>0 0 0 0 0 -1.5708</pose>
          <geometry>
            <mesh>
              <scale>0.04 0.04 0.04</scale>
              <uri>model://suv/meshes/suv.obj</uri>
            </mesh>
          </geometry>
        </visual>
        <self_collide>0</self_collide>
        <kinematic>0</kinematic>
        <enable_wind>0</enable_wind>
      </link>
      <pose>3.96453 12.3301 0 0 -0 0</pose>
    </model>
    <model name='suv_clone_0_clone_9_clone_4_clone_5'>
      <static>1</static>
      <link name='link'>
        <collision name='collision'>
          <pose>0 0 0 0 0 -1.5708</pose>
          <geometry>
            <mesh>
              <scale>0.04 0.04 0.04</scale>
              <uri>model://suv/meshes/suv.obj</uri>
            </mesh>
          </geometry>
          <max_contacts>10</max_contacts>
          <surface>
            <contact>
              <ode/>
            </contact>
            <bounce/>
            <friction>
              <torsional>
                <ode/>
              </torsional>
              <ode/>
            </friction>
          </surface>
        </collision>
        <visual name='visual'>
          <pose>0 0 0 0 0 -1.5708</pose>
          <geometry>
            <mesh>
              <scale>0.04 0.04 0.04</scale>
              <uri>model://suv/meshes/suv.obj</uri>
            </mesh>
          </geometry>
        </visual>
        <self_collide>0</self_collide>
        <kinematic>0</kinematic>
        <enable_wind>0</enable_wind>
      </link>
      <pose>3.96967 14.3206 0 0 -0 0</pose>
    </model>
    <model name='suv_clone_0_clone_9_clone_4_clone_6'>
      <static>1</static>
      <link name='link'>
        <collision name='collision'>
          <pose>0 0 0 0 0 -1.5708</pose>
          <geometry>
            <mesh>
              <scale>0.04 0.04 0.04</scale>
              <uri>model://suv/meshes/suv.obj</uri>
            </mesh>
          </geometry>
          <max_contacts>10</max_contacts>
          <surface>
            <contact>
              <ode/>
            </contact>
            <bounce/>
            <friction>
              <torsional>
                <ode/>
              </torsional>
              <ode/>
            </friction>
          </surface>
        </collision>
        <visual name='visual'>
          <pose>0 0 0 0 0 -1.5708</pose>
          <geometry>
            <mesh>
              <scale>0.04 0.04 0.04</scale>
              <uri>model://suv/meshes/suv.obj</uri>
            </mesh>
          </geometry>
        </visual>
        <self_collide>0</self_collide>
        <kinematic>0</kinematic>
        <enable_wind>0</enable_wind>
      </link>
      <pose>4.09085 16.2783 0 0 -0 0</pose>
    </model>
    <model name='suv_clone_0_clone_9_clone_4_clone_7'>
      <static>1</static>
      <link name='link'>
        <collision name='collision'>
          <pose>0 0 0 0 0 -1.5708</pose>
          <geometry>
            <mesh>
              <scale>0.04 0.04 0.04</scale>
              <uri>model://suv/meshes/suv.obj</uri>
            </mesh>
          </geometry>
          <max_contacts>10</max_contacts>
          <surface>
            <contact>
              <ode/>
            </contact>
            <bounce/>
            <friction>
              <torsional>
                <ode/>
              </torsional>
              <ode/>
            </friction>
          </surface>
        </collision>
        <visual name='visual'>
          <pose>0 0 0 0 0 -1.5708</pose>
          <geometry>
            <mesh>
              <scale>0.04 0.04 0.04</scale>
              <uri>model://suv/meshes/suv.obj</uri>
            </mesh>
          </geometry>
        </visual>
        <self_collide>0</self_collide>
        <kinematic>0</kinematic>
        <enable_wind>0</enable_wind>
      </link>
      <pose>4.03469 18.1829 0 0 -0 0</pose>
    </model>
    <model name='unit_box_1'>
      <pose>-5.75704 -2.44271 0.5 0 -0 0</pose>
      <link name='link'>
        <inertial>
          <mass>1</mass>
          <inertia>
            <ixx>0.166667</ixx>
            <ixy>0</ixy>
            <ixz>0</ixz>
            <iyy>0.166667</iyy>
            <iyz>0</iyz>
            <izz>0.166667</izz>
          </inertia>
          <pose>0 0 0 0 -0 0</pose>
        </inertial>
        <collision name='collision'>
          <geometry>
            <box>
              <size>1 1 1</size>
            </box>
          </geometry>
          <max_contacts>10</max_contacts>
          <surface>
            <contact>
              <ode/>
            </contact>
            <bounce/>
            <friction>
              <torsional>
                <ode/>
              </torsional>
              <ode/>
            </friction>
          </surface>
        </collision>
        <visual name='visual'>
          <geometry>
            <box>
              <size>1 1 1</size>
            </box>
          </geometry>
          <material>
            <script>
              <name>Gazebo/Grey</name>
              <uri>file://media/materials/scripts/gazebo.material</uri>
            </script>
          </material>
        </visual>
        <self_collide>0</self_collide>
        <enable_wind>0</enable_wind>
        <kinematic>0</kinematic>
      </link>
    </model>
    <model name='unit_box_2'>
      <pose>-5.62538 2.16545 0.5 0 -0 0</pose>
      <link name='link'>
        <inertial>
          <mass>1</mass>
          <inertia>
            <ixx>0.166667</ixx>
            <ixy>0</ixy>
            <ixz>0</ixz>
            <iyy>0.166667</iyy>
            <iyz>0</iyz>
            <izz>0.166667</izz>
          </inertia>
          <pose>0 0 0 0 -0 0</pose>
        </inertial>
        <collision name='collision'>
          <geometry>
            <box>
              <size>1 1 1</size>
            </box>
          </geometry>
          <max_contacts>10</max_contacts>
          <surface>
            <contact>
              <ode/>
            </contact>
            <bounce/>
            <friction>
              <torsional>
                <ode/>
              </torsional>
              <ode/>
            </friction>
          </surface>
        </collision>
        <visual name='visual'>
          <geometry>
            <box>
              <size>1 1 1</size>
            </box>
          </geometry>
          <material>
            <script>
              <name>Gazebo/Grey</name>
              <uri>file://media/materials/scripts/gazebo.material</uri>
            </script>
          </material>
        </visual>
        <self_collide>0</self_collide>
        <enable_wind>0</enable_wind>
        <kinematic>0</kinematic>
      </link>
    </model>
    <model name='unit_box_3'>
      <pose>-5.75811 -3.94245 0.5 0 -0 0</pose>
      <link name='link'>
        <inertial>
          <mass>1</mass>
          <inertia>
            <ixx>0.166667</ixx>
            <ixy>0</ixy>
            <ixz>0</ixz>
            <iyy>0.166667</iyy>
            <iyz>0</iyz>
            <izz>0.166667</izz>
          </inertia>
          <pose>0 0 0 0 -0 0</pose>
        </inertial>
        <collision name='collision'>
          <geometry>
            <box>
              <size>1 1 1</size>
            </box>
          </geometry>
          <max_contacts>10</max_contacts>
          <surface>
            <contact>
              <ode/>
            </contact>
            <bounce/>
            <friction>
              <torsional>
                <ode/>
              </torsional>
              <ode/>
            </friction>
          </surface>
        </collision>
        <visual name='visual'>
          <geometry>
            <box>
              <size>1 1 1</size>
            </box>
          </geometry>
          <material>
            <script>
              <name>Gazebo/Grey</name>
              <uri>file://media/materials/scripts/gazebo.material</uri>
            </script>
          </material>
        </visual>
        <self_collide>0</self_collide>
        <enable_wind>0</enable_wind>
        <kinematic>0</kinematic>
      </link>
    </model>
    <model name='swerve_drive_robot'>
      <link name='base_link'>
        <inertial>
          <pose>0 0 0.272727 0 -0 0</pose>
          <mass>1.1</mass>
          <inertia>
            <ixx>10.8183</ixx>
            <ixy>0</ixy>
            <ixz>0</ixz>
            <iyy>10.8183</iyy>
            <iyz>0</iyz>
            <izz>10.0002</izz>
          </inertia>
        </inertial>
        <collision name='base_link_collision'>
          <pose>0 0 0 0 -0 0</pose>
          <geometry>
            <box>
              <size>6 3 0.2</size>
            </box>
          </geometry>
          <surface>
            <contact>
              <ode/>
            </contact>
            <friction>
              <ode/>
              <torsional>
                <ode/>
              </torsional>
            </friction>
            <bounce/>
          </surface>
          <max_contacts>10</max_contacts>
        </collision>
        <collision name='base_link_fixed_joint_lump__imu_link_collision_1'>
          <pose>0 0 3 0 -0 0</pose>
          <geometry>
            <box>
              <size>0.1 0.1 0.1</size>
            </box>
          </geometry>
          <surface>
            <contact>
              <ode/>
            </contact>
            <friction>
              <ode/>
              <torsional>
                <ode/>
              </torsional>
            </friction>
            <bounce/>
          </surface>
          <max_contacts>10</max_contacts>
        </collision>
        <visual name='base_link_visual'>
          <pose>0 0 0 0 -0 0</pose>
          <geometry>
            <box>
              <size>6 3 0.2</size>
            </box>
          </geometry>
          <material>
            <script>
              <name>Gazebo/Blue</name>
              <uri>file://media/materials/scripts/gazebo.material</uri>
            </script>
          </material>
        </visual>
        <visual name='base_link_fixed_joint_lump__imu_link_visual_1'>
          <pose>0 0 3 0 -0 0</pose>
          <geometry>
            <box>
              <size>0.1 0.1 0.1</size>
            </box>
          </geometry>
        </visual>
        <gravity>1</gravity>
        <sensor name='imu_sensor' type='imu'>
          <always_on>1</always_on>
          <update_rate>50</update_rate>
          <visualize>1</visualize>
          <topic>__default_topic__</topic>
          <plugin name='imu_plugin' filename='libgazebo_ros_imu_sensor.so'>
            <topicName>/imu/data_raw</topicName>
            <bodyName>imu_link</bodyName>
            <updateRateHZ>50.0</updateRateHZ>
            <gaussianNoise>0.0</gaussianNoise>
            <xyzOffset>0 0 0</xyzOffset>
            <rpyOffset>0 0 0</rpyOffset>
            <frameName>imu_link</frameName>
            <initialOrientationAsReference>0</initialOrientationAsReference>
            <robotNamespace>/</robotNamespace>
          </plugin>
          <pose>0 0 3 0 -0 0</pose>
          <imu/>
        </sensor>
        <sensor name='laser_frame_0' type='ray'>
          <visualize>1</visualize>
          <update_rate>15</update_rate>
          <ray>
            <scan>
              <horizontal>
                <samples>160</samples>
                <resolution>1</resolution>
                <min_angle>-1.0472</min_angle>
                <max_angle>1.0472</max_angle>
              </horizontal>
              <vertical>
                <samples>1</samples>
                <min_angle>0</min_angle>
                <max_angle>0</max_angle>
              </vertical>
            </scan>
            <range>
              <min>0.2</min>
              <max>8</max>
              <resolution>0.01</resolution>
            </range>
          </ray>
          <plugin name='laser_frame_0' filename='libgazebo_ros_laser.so'>
            <topicName>/cygbot/scan/2d/0</topicName>
            <frameName>laser_frame_0</frameName>
            <robotNamespace>/</robotNamespace>
          </plugin>
          <pose>2.875 1.3 -2 0 -0 0</pose>
        </sensor>
        <sensor name='point_frame_0' type='gpu_ray'>
          <visualize>0</visualize>
          <update_rate>15</update_rate>
          <ray>
            <scan>
              <horizontal>
                <samples>160</samples>
                <resolution>1</resolution>
                <min_angle>-1.0472</min_angle>
                <max_angle>1.0472</max_angle>
              </horizontal>
              <vertical>
                <samples>60</samples>
                <resolution>1</resolution>
                <min_angle>-0.567232</min_angle>
                <max_angle>0.567232</max_angle>
              </vertical>
            </scan>
            <range>
              <min>0.05</min>
              <max>2</max>
              <resolution>0.01</resolution>
            </range>
            <noise>
              <type>gaussian</type>
              <mean>0</mean>
              <stddev>0.01</stddev>
            </noise>
          </ray>
          <plugin name='point_frame_0' filename='libgazebo_ros_velodyne_gpu_laser.so'>
            <topicName>/cygbot/point/3d/0</topicName>
            <frameName>laser_frame_0</frameName>
            <robotNamespace>/</robotNamespace>
          </plugin>
          <pose>2.875 1.3 -2 0 -0 0</pose>
        </sensor>
        <sensor name='laser_frame_1' type='ray'>
          <visualize>1</visualize>
          <update_rate>15</update_rate>
          <ray>
            <scan>
              <horizontal>
                <samples>160</samples>
                <resolution>1</resolution>
                <min_angle>-1.0472</min_angle>
                <max_angle>1.0472</max_angle>
              </horizontal>
              <vertical>
                <samples>1</samples>
                <min_angle>0</min_angle>
                <max_angle>0</max_angle>
              </vertical>
            </scan>
            <range>
              <min>0.2</min>
              <max>8</max>
              <resolution>0.01</resolution>
            </range>
          </ray>
          <plugin name='laser_frame_1' filename='libgazebo_ros_laser.so'>
            <topicName>/cygbot/scan/2d/1</topicName>
            <frameName>laser_frame_1</frameName>
            <robotNamespace>/</robotNamespace>
          </plugin>
          <pose>2.875 -1.3 -2 0 -0 0</pose>
        </sensor>
        <sensor name='point_frame_1' type='gpu_ray'>
          <visualize>0</visualize>
          <update_rate>15</update_rate>
          <ray>
            <scan>
              <horizontal>
                <samples>160</samples>
                <resolution>1</resolution>
                <min_angle>-1.0472</min_angle>
                <max_angle>1.0472</max_angle>
              </horizontal>
              <vertical>
                <samples>60</samples>
                <resolution>1</resolution>
                <min_angle>-0.567232</min_angle>
                <max_angle>0.567232</max_angle>
              </vertical>
            </scan>
            <range>
              <min>0.05</min>
              <max>2</max>
              <resolution>0.01</resolution>
            </range>
            <noise>
              <type>gaussian</type>
              <mean>0</mean>
              <stddev>0.01</stddev>
            </noise>
          </ray>
          <plugin name='point_frame_1' filename='libgazebo_ros_velodyne_gpu_laser.so'>
            <topicName>/cygbot/point/3d/1</topicName>
            <frameName>laser_frame_1</frameName>
            <robotNamespace>/</robotNamespace>
          </plugin>
          <pose>2.875 -1.3 -2 0 -0 0</pose>
        </sensor>
        <sensor name='laser_frame_2' type='ray'>
          <visualize>1</visualize>
          <update_rate>15</update_rate>
          <ray>
            <scan>
              <horizontal>
                <samples>160</samples>
                <resolution>1</resolution>
                <min_angle>-1.0472</min_angle>
                <max_angle>1.0472</max_angle>
              </horizontal>
              <vertical>
                <samples>1</samples>
                <min_angle>0</min_angle>
                <max_angle>0</max_angle>
              </vertical>
            </scan>
            <range>
              <min>0.2</min>
              <max>8</max>
              <resolution>0.01</resolution>
            </range>
          </ray>
          <plugin name='laser_frame_2' filename='libgazebo_ros_laser.so'>
            <topicName>/cygbot/scan/2d/2</topicName>
            <frameName>laser_frame_2</frameName>
            <robotNamespace>/</robotNamespace>
          </plugin>
          <pose>-2.875 -1.3 -2 0 -0 3.14159</pose>
        </sensor>
        <sensor name='point_frame_2' type='gpu_ray'>
          <visualize>0</visualize>
          <update_rate>15</update_rate>
          <ray>
            <scan>
              <horizontal>
                <samples>160</samples>
                <resolution>1</resolution>
                <min_angle>-1.0472</min_angle>
                <max_angle>1.0472</max_angle>
              </horizontal>
              <vertical>
                <samples>60</samples>
                <resolution>1</resolution>
                <min_angle>-0.567232</min_angle>
                <max_angle>0.567232</max_angle>
              </vertical>
            </scan>
            <range>
              <min>0.05</min>
              <max>2</max>
              <resolution>0.01</resolution>
            </range>
            <noise>
              <type>gaussian</type>
              <mean>0</mean>
              <stddev>0.01</stddev>
            </noise>
          </ray>
          <plugin name='point_frame_2' filename='libgazebo_ros_velodyne_gpu_laser.so'>
            <topicName>/cygbot/point/3d/2</topicName>
            <frameName>laser_frame_2</frameName>
            <robotNamespace>/</robotNamespace>
          </plugin>
          <pose>-2.875 -1.3 -2 0 -0 3.14159</pose>
        </sensor>
        <sensor name='laser_frame_3' type='ray'>
          <visualize>1</visualize>
          <update_rate>15</update_rate>
          <ray>
            <scan>
              <horizontal>
                <samples>160</samples>
                <resolution>1</resolution>
                <min_angle>-1.0472</min_angle>
                <max_angle>1.0472</max_angle>
              </horizontal>
              <vertical>
                <samples>1</samples>
                <min_angle>0</min_angle>
                <max_angle>0</max_angle>
              </vertical>
            </scan>
            <range>
              <min>0.2</min>
              <max>8</max>
              <resolution>0.01</resolution>
            </range>
          </ray>
          <plugin name='laser_frame_3' filename='libgazebo_ros_laser.so'>
            <topicName>/cygbot/scan/2d/3</topicName>
            <frameName>laser_frame_3</frameName>
            <robotNamespace>/</robotNamespace>
          </plugin>
          <pose>-2.875 1.3 -2 0 -0 3.14159</pose>
        </sensor>
        <sensor name='point_frame_3' type='gpu_ray'>
          <visualize>0</visualize>
          <update_rate>15</update_rate>
          <ray>
            <scan>
              <horizontal>
                <samples>160</samples>
                <resolution>1</resolution>
                <min_angle>-1.0472</min_angle>
                <max_angle>1.0472</max_angle>
              </horizontal>
              <vertical>
                <samples>60</samples>
                <resolution>1</resolution>
                <min_angle>-0.567232</min_angle>
                <max_angle>0.567232</max_angle>
              </vertical>
            </scan>
            <range>
              <min>0.05</min>
              <max>2</max>
              <resolution>0.01</resolution>
            </range>
            <noise>
              <type>gaussian</type>
              <mean>0</mean>
              <stddev>0.01</stddev>
            </noise>
          </ray>
          <plugin name='point_frame_3' filename='libgazebo_ros_velodyne_gpu_laser.so'>
            <topicName>/cygbot/point/3d/3</topicName>
            <frameName>laser_frame_3</frameName>
            <robotNamespace>/</robotNamespace>
          </plugin>
          <pose>-2.875 1.3 -2 0 -0 3.14159</pose>
        </sensor>
        <sensor name='laser_frame_4' type='ray'>
          <visualize>1</visualize>
          <update_rate>15</update_rate>
          <ray>
            <scan>
              <horizontal>
                <samples>160</samples>
                <resolution>1</resolution>
                <min_angle>-1.0472</min_angle>
                <max_angle>1.0472</max_angle>
              </horizontal>
              <vertical>
                <samples>1</samples>
                <min_angle>0</min_angle>
                <max_angle>0</max_angle>
              </vertical>
            </scan>
            <range>
              <min>0.2</min>
              <max>8</max>
              <resolution>0.01</resolution>
            </range>
          </ray>
          <plugin name='laser_frame_4' filename='libgazebo_ros_laser.so'>
            <topicName>/cygbot/scan/2d/4</topicName>
            <frameName>laser_frame_4</frameName>
            <robotNamespace>/</robotNamespace>
          </plugin>
          <pose>2.875 1.3 -2 0 -0 1.5708</pose>
        </sensor>
        <sensor name='point_frame_4' type='gpu_ray'>
          <visualize>0</visualize>
          <update_rate>15</update_rate>
          <ray>
            <scan>
              <horizontal>
                <samples>160</samples>
                <resolution>1</resolution>
                <min_angle>-1.0472</min_angle>
                <max_angle>1.0472</max_angle>
              </horizontal>
              <vertical>
                <samples>60</samples>
                <resolution>1</resolution>
                <min_angle>-0.567232</min_angle>
                <max_angle>0.567232</max_angle>
              </vertical>
            </scan>
            <range>
              <min>0.05</min>
              <max>2</max>
              <resolution>0.01</resolution>
            </range>
            <noise>
              <type>gaussian</type>
              <mean>0</mean>
              <stddev>0.01</stddev>
            </noise>
          </ray>
          <plugin name='point_frame_4' filename='libgazebo_ros_velodyne_gpu_laser.so'>
            <topicName>/cygbot/point/3d/4</topicName>
            <frameName>laser_frame_4</frameName>
            <robotNamespace>/</robotNamespace>
          </plugin>
          <pose>2.875 1.3 -2 0 -0 1.5708</pose>
        </sensor>
        <sensor name='laser_frame_5' type='ray'>
          <visualize>1</visualize>
          <update_rate>15</update_rate>
          <ray>
            <scan>
              <horizontal>
                <samples>160</samples>
                <resolution>1</resolution>
                <min_angle>-1.0472</min_angle>
                <max_angle>1.0472</max_angle>
              </horizontal>
              <vertical>
                <samples>1</samples>
                <min_angle>0</min_angle>
                <max_angle>0</max_angle>
              </vertical>
            </scan>
            <range>
              <min>0.2</min>
              <max>8</max>
              <resolution>0.01</resolution>
            </range>
          </ray>
          <plugin name='laser_frame_5' filename='libgazebo_ros_laser.so'>
            <topicName>/cygbot/scan/2d/5</topicName>
            <frameName>laser_frame_5</frameName>
            <robotNamespace>/</robotNamespace>
          </plugin>
          <pose>2.875 -1.3 -2 0 0 -1.5708</pose>
        </sensor>
        <sensor name='point_frame_5' type='gpu_ray'>
          <visualize>0</visualize>
          <update_rate>15</update_rate>
          <ray>
            <scan>
              <horizontal>
                <samples>160</samples>
                <resolution>1</resolution>
                <min_angle>-1.0472</min_angle>
                <max_angle>1.0472</max_angle>
              </horizontal>
              <vertical>
                <samples>60</samples>
                <resolution>1</resolution>
                <min_angle>-0.567232</min_angle>
                <max_angle>0.567232</max_angle>
              </vertical>
            </scan>
            <range>
              <min>0.05</min>
              <max>2</max>
              <resolution>0.01</resolution>
            </range>
            <noise>
              <type>gaussian</type>
              <mean>0</mean>
              <stddev>0.01</stddev>
            </noise>
          </ray>
          <plugin name='point_frame_5' filename='libgazebo_ros_velodyne_gpu_laser.so'>
            <topicName>/cygbot/point/3d/5</topicName>
            <frameName>laser_frame_5</frameName>
            <robotNamespace>/</robotNamespace>
          </plugin>
          <pose>2.875 -1.3 -2 0 0 -1.5708</pose>
        </sensor>
        <sensor name='laser_frame_6' type='ray'>
          <visualize>1</visualize>
          <update_rate>15</update_rate>
          <ray>
            <scan>
              <horizontal>
                <samples>160</samples>
                <resolution>1</resolution>
                <min_angle>-1.0472</min_angle>
                <max_angle>1.0472</max_angle>
              </horizontal>
              <vertical>
                <samples>1</samples>
                <min_angle>0</min_angle>
                <max_angle>0</max_angle>
              </vertical>
            </scan>
            <range>
              <min>0.2</min>
              <max>8</max>
              <resolution>0.01</resolution>
            </range>
          </ray>
          <plugin name='laser_frame_6' filename='libgazebo_ros_laser.so'>
            <topicName>/cygbot/scan/2d/6</topicName>
            <frameName>laser_frame_6</frameName>
            <robotNamespace>/</robotNamespace>
          </plugin>
          <pose>-2.875 -1.3 -2 0 0 -1.5708</pose>
        </sensor>
        <sensor name='point_frame_6' type='gpu_ray'>
          <visualize>0</visualize>
          <update_rate>15</update_rate>
          <ray>
            <scan>
              <horizontal>
                <samples>160</samples>
                <resolution>1</resolution>
                <min_angle>-1.0472</min_angle>
                <max_angle>1.0472</max_angle>
              </horizontal>
              <vertical>
                <samples>60</samples>
                <resolution>1</resolution>
                <min_angle>-0.567232</min_angle>
                <max_angle>0.567232</max_angle>
              </vertical>
            </scan>
            <range>
              <min>0.05</min>
              <max>2</max>
              <resolution>0.01</resolution>
            </range>
            <noise>
              <type>gaussian</type>
              <mean>0</mean>
              <stddev>0.01</stddev>
            </noise>
          </ray>
          <plugin name='point_frame_6' filename='libgazebo_ros_velodyne_gpu_laser.so'>
            <topicName>/cygbot/point/3d/6</topicName>
            <frameName>laser_frame_6</frameName>
            <robotNamespace>/</robotNamespace>
          </plugin>
          <pose>-2.875 -1.3 -2 0 0 -1.5708</pose>
        </sensor>
        <sensor name='laser_frame_7' type='ray'>
          <visualize>1</visualize>
          <update_rate>15</update_rate>
          <ray>
            <scan>
              <horizontal>
                <samples>160</samples>
                <resolution>1</resolution>
                <min_angle>-1.0472</min_angle>
                <max_angle>1.0472</max_angle>
              </horizontal>
              <vertical>
                <samples>1</samples>
                <min_angle>0</min_angle>
                <max_angle>0</max_angle>
              </vertical>
            </scan>
            <range>
              <min>0.2</min>
              <max>8</max>
              <resolution>0.01</resolution>
            </range>
          </ray>
          <plugin name='laser_frame_7' filename='libgazebo_ros_laser.so'>
            <topicName>/cygbot/scan/2d/7</topicName>
            <frameName>laser_frame_7</frameName>
            <robotNamespace>/</robotNamespace>
          </plugin>
          <pose>-2.875 1.3 -2 0 -0 1.5708</pose>
        </sensor>
        <sensor name='point_frame_7' type='gpu_ray'>
          <visualize>0</visualize>
          <update_rate>15</update_rate>
          <ray>
            <scan>
              <horizontal>
                <samples>160</samples>
                <resolution>1</resolution>
                <min_angle>-1.0472</min_angle>
                <max_angle>1.0472</max_angle>
              </horizontal>
              <vertical>
                <samples>60</samples>
                <resolution>1</resolution>
                <min_angle>-0.567232</min_angle>
                <max_angle>0.567232</max_angle>
              </vertical>
            </scan>
            <range>
              <min>0.05</min>
              <max>2</max>
              <resolution>0.01</resolution>
            </range>
            <noise>
              <type>gaussian</type>
              <mean>0</mean>
              <stddev>0.01</stddev>
            </noise>
          </ray>
          <plugin name='point_frame_7' filename='libgazebo_ros_velodyne_gpu_laser.so'>
            <topicName>/cygbot/point/3d/7</topicName>
            <frameName>laser_frame_7</frameName>
            <robotNamespace>/</robotNamespace>
          </plugin>
          <pose>-2.875 1.3 -2 0 -0 1.5708</pose>
        </sensor>
        <self_collide>0</self_collide>
        <enable_wind>0</enable_wind>
        <kinematic>0</kinematic>
      </link>
      <joint name='front_left_steering_joint' type='revolute'>
        <pose relative_to='base_link'>2.825 1.25 -0.1 0 -0 0</pose>
        <parent>base_link</parent>
        <child>front_left_steering_link</child>
        <axis>
          <xyz>0 0 -1</xyz>
          <limit>
            <lower>-1e+16</lower>
            <upper>1e+16</upper>
          </limit>
          <dynamics>
            <damping>1</damping>
            <friction>0.5</friction>
            <spring_reference>0</spring_reference>
            <spring_stiffness>0</spring_stiffness>
          </dynamics>
        </axis>
      </joint>
      <link name='front_left_steering_link'>
        <pose relative_to='front_left_steering_joint'>0 0 0 0 -0 0</pose>
        <inertial>
          <pose>0 0 -0.133333 0 -0 0</pose>
          <mass>3</mass>
          <inertia>
            <ixx>0.369667</ixx>
            <ixy>0</ixy>
            <ixz>0</ixz>
            <iyy>0.369667</iyy>
            <iyz>0</iyz>
            <izz>0.03</izz>
          </inertia>
        </inertial>
        <collision name='front_left_steering_link_collision'>
          <pose>0 0 0 0 -0 0</pose>
          <geometry>
            <cylinder>
              <length>0.2</length>
              <radius>0.15</radius>
            </cylinder>
          </geometry>
          <max_contacts>10</max_contacts>
          <surface>
            <contact>
              <ode/>
            </contact>
            <bounce/>
            <friction>
              <torsional>
                <ode/>
              </torsional>
              <ode/>
            </friction>
          </surface>
        </collision>
        <collision name='front_left_steering_link_fixed_joint_lump__front_left_pillar_link_collision_1'>
          <pose>0 0 -1.2 0 -0 0</pose>
          <geometry>
            <cylinder>
              <length>2</length>
              <radius>0.1</radius>
            </cylinder>
          </geometry>
          <surface>
            <contact>
              <ode/>
            </contact>
            <friction>
              <ode/>
              <torsional>
                <ode/>
              </torsional>
            </friction>
            <bounce/>
          </surface>
          <max_contacts>10</max_contacts>
        </collision>
        <visual name='front_left_steering_link_visual'>
          <pose>0 0 0 0 -0 0</pose>
          <geometry>
            <cylinder>
              <length>0.2</length>
              <radius>0.15</radius>
            </cylinder>
          </geometry>
        </visual>
        <visual name='front_left_steering_link_fixed_joint_lump__front_left_pillar_link_visual_1'>
          <pose>0 0 -1.2 0 -0 0</pose>
          <geometry>
            <cylinder>
              <length>2</length>
              <radius>0.1</radius>
            </cylinder>
          </geometry>
          <material>
            <script>
              <name>Gazebo/White</name>
              <uri>file://media/materials/scripts/gazebo.material</uri>
            </script>
          </material>
        </visual>
        <self_collide>0</self_collide>
        <enable_wind>0</enable_wind>
        <kinematic>0</kinematic>
      </link>
      <joint name='front_left_suspension_joint' type='prismatic'>
        <pose relative_to='front_left_steering_link'>0 0 -2.2 0 -0 0</pose>
        <parent>front_left_steering_link</parent>
        <child>front_left_suspension_link</child>
        <axis>
          <xyz>0 0 1</xyz>
          <limit>
            <lower>-0.075</lower>
            <upper>0.075</upper>
            <effort>1000</effort>
            <velocity>1</velocity>
          </limit>
          <dynamics>
            <damping>15</damping>
            <friction>0.01</friction>
            <spring_reference>0</spring_reference>
            <spring_stiffness>800</spring_stiffness>
          </dynamics>
        </axis>
        <physics>
          <ode>
            <limit>
              <cfm>0</cfm>
              <erp>0.2</erp>
            </limit>
          </ode>
        </physics>
        <springDamping>80.0</springDamping>
      </joint>
      <link name='front_left_suspension_link'>
        <pose relative_to='front_left_suspension_joint'>0 0 0 0 -0 0</pose>
        <inertial>
          <pose>0 0 0 0 -0 0</pose>
          <mass>0.5</mass>
          <inertia>
            <ixx>0.005</ixx>
            <ixy>0</ixy>
            <ixz>0</ixz>
            <iyy>0.005</iyy>
            <iyz>0</iyz>
            <izz>0.005</izz>
          </inertia>
        </inertial>
        <collision name='front_left_suspension_link_collision'>
          <pose>0 0 0 0 -0 0</pose>
          <geometry>
            <cylinder>
              <length>0.1</length>
              <radius>0.1</radius>
            </cylinder>
          </geometry>
          <max_contacts>10</max_contacts>
          <surface>
            <contact>
              <ode/>
            </contact>
            <bounce/>
            <friction>
              <torsional>
                <ode/>
              </torsional>
              <ode/>
            </friction>
          </surface>
        </collision>
        <visual name='front_left_suspension_link_visual'>
          <pose>0 0 0 0 -0 0</pose>
          <geometry>
            <cylinder>
              <length>0.1</length>
              <radius>0.1</radius>
            </cylinder>
          </geometry>
        </visual>
        <self_collide>0</self_collide>
        <enable_wind>0</enable_wind>
        <kinematic>0</kinematic>
      </link>
      <joint name='front_left_wheel_joint' type='revolute'>
        <pose relative_to='front_left_suspension_link'>0 0 -0.202 0 -0 0</pose>
        <parent>front_left_suspension_link</parent>
        <child>front_left_wheel_link</child>
        <axis>
          <xyz>0 -1 0</xyz>
          <limit>
            <lower>-1e+16</lower>
            <upper>1e+16</upper>
          </limit>
          <dynamics>
            <damping>10</damping>
            <friction>0</friction>
            <spring_reference>0</spring_reference>
            <spring_stiffness>0</spring_stiffness>
          </dynamics>
        </axis>
      </joint>
      <link name='front_left_wheel_link'>
        <pose relative_to='front_left_wheel_joint'>0 0 0 0 -0 0</pose>
        <inertial>
          <pose>0 0 0 0 -0 0</pose>
          <mass>0.5</mass>
          <inertia>
            <ixx>0.001</ixx>
            <ixy>0</ixy>
            <ixz>0</ixz>
            <iyy>0.001</iyy>
            <iyz>0</iyz>
            <izz>0.001</izz>
          </inertia>
        </inertial>
        <collision name='front_left_wheel_link_collision'>
          <pose>0 0 0 0 -0 0</pose>
          <geometry>
            <cylinder>
              <length>0.1</length>
              <radius>0.102</radius>
            </cylinder>
          </geometry>
          <surface>
            <contact>
              <ode>
                <kp>10000</kp>
                <kd>300</kd>
              </ode>
            </contact>
            <friction>
              <ode>
                <mu>0.6</mu>
                <mu2>0.6</mu2>
              </ode>
              <torsional>
                <ode/>
              </torsional>
            </friction>
            <bounce/>
          </surface>
          <max_contacts>10</max_contacts>
        </collision>
        <visual name='front_left_wheel_link_visual'>
          <pose>0 0 0 0 -0 0</pose>
          <geometry>
            <mesh>
              <scale>1 1 1</scale>
              <uri>/home/loookup/robotics/happy_robo/src/happy_robot/meshes/wheel.dae</uri>
            </mesh>
          </geometry>
          <material>
            <script>
              <name>Gazebo/Black</name>
              <uri>file://media/materials/scripts/gazebo.material</uri>
            </script>
          </material>
        </visual>
        <self_collide>0</self_collide>
        <enable_wind>0</enable_wind>
        <kinematic>0</kinematic>
      </link>
      <joint name='front_right_steering_joint' type='revolute'>
        <pose relative_to='base_link'>2.825 -1.25 -0.1 0 -0 0</pose>
        <parent>base_link</parent>
        <child>front_right_steering_link</child>
        <axis>
          <xyz>0 0 -1</xyz>
          <limit>
            <lower>-1e+16</lower>
            <upper>1e+16</upper>
          </limit>
          <dynamics>
            <damping>1</damping>
            <friction>0.5</friction>
            <spring_reference>0</spring_reference>
            <spring_stiffness>0</spring_stiffness>
          </dynamics>
        </axis>
      </joint>
      <link name='front_right_steering_link'>
        <pose relative_to='front_right_steering_joint'>0 0 0 0 -0 0</pose>
        <inertial>
          <pose>0 0 -0.133333 0 -0 0</pose>
          <mass>3</mass>
          <inertia>
            <ixx>0.369667</ixx>
            <ixy>0</ixy>
            <ixz>0</ixz>
            <iyy>0.369667</iyy>
            <iyz>0</iyz>
            <izz>0.03</izz>
          </inertia>
        </inertial>
        <collision name='front_right_steering_link_collision'>
          <pose>0 0 0 0 -0 0</pose>
          <geometry>
            <cylinder>
              <length>0.2</length>
              <radius>0.15</radius>
            </cylinder>
          </geometry>
          <max_contacts>10</max_contacts>
          <surface>
            <contact>
              <ode/>
            </contact>
            <bounce/>
            <friction>
              <torsional>
                <ode/>
              </torsional>
              <ode/>
            </friction>
          </surface>
        </collision>
        <collision name='front_right_steering_link_fixed_joint_lump__front_right_pillar_link_collision_1'>
          <pose>0 0 -1.2 0 -0 0</pose>
          <geometry>
            <cylinder>
              <length>2</length>
              <radius>0.1</radius>
            </cylinder>
          </geometry>
          <surface>
            <contact>
              <ode/>
            </contact>
            <friction>
              <ode/>
              <torsional>
                <ode/>
              </torsional>
            </friction>
            <bounce/>
          </surface>
          <max_contacts>10</max_contacts>
        </collision>
        <visual name='front_right_steering_link_visual'>
          <pose>0 0 0 0 -0 0</pose>
          <geometry>
            <cylinder>
              <length>0.2</length>
              <radius>0.15</radius>
            </cylinder>
          </geometry>
        </visual>
        <visual name='front_right_steering_link_fixed_joint_lump__front_right_pillar_link_visual_1'>
          <pose>0 0 -1.2 0 -0 0</pose>
          <geometry>
            <cylinder>
              <length>2</length>
              <radius>0.1</radius>
            </cylinder>
          </geometry>
          <material>
            <script>
              <name>Gazebo/White</name>
              <uri>file://media/materials/scripts/gazebo.material</uri>
            </script>
          </material>
        </visual>
        <self_collide>0</self_collide>
        <enable_wind>0</enable_wind>
        <kinematic>0</kinematic>
      </link>
      <joint name='front_right_suspension_joint' type='prismatic'>
        <pose relative_to='front_right_steering_link'>0 0 -2.2 0 -0 0</pose>
        <parent>front_right_steering_link</parent>
        <child>front_right_suspension_link</child>
        <axis>
          <xyz>0 0 1</xyz>
          <limit>
            <lower>-0.075</lower>
            <upper>0.075</upper>
            <effort>1000</effort>
            <velocity>1</velocity>
          </limit>
          <dynamics>
            <damping>15</damping>
            <friction>0.01</friction>
            <spring_reference>0</spring_reference>
            <spring_stiffness>800</spring_stiffness>
          </dynamics>
        </axis>
        <physics>
          <ode>
            <limit>
              <cfm>0</cfm>
              <erp>0.2</erp>
            </limit>
          </ode>
        </physics>
        <springDamping>80.0</springDamping>
      </joint>
      <link name='front_right_suspension_link'>
        <pose relative_to='front_right_suspension_joint'>0 0 0 0 -0 0</pose>
        <inertial>
          <pose>0 0 0 0 -0 0</pose>
          <mass>0.5</mass>
          <inertia>
            <ixx>0.005</ixx>
            <ixy>0</ixy>
            <ixz>0</ixz>
            <iyy>0.005</iyy>
            <iyz>0</iyz>
            <izz>0.005</izz>
          </inertia>
        </inertial>
        <collision name='front_right_suspension_link_collision'>
          <pose>0 0 0 0 -0 0</pose>
          <geometry>
            <cylinder>
              <length>0.1</length>
              <radius>0.1</radius>
            </cylinder>
          </geometry>
          <max_contacts>10</max_contacts>
          <surface>
            <contact>
              <ode/>
            </contact>
            <bounce/>
            <friction>
              <torsional>
                <ode/>
              </torsional>
              <ode/>
            </friction>
          </surface>
        </collision>
        <visual name='front_right_suspension_link_visual'>
          <pose>0 0 0 0 -0 0</pose>
          <geometry>
            <cylinder>
              <length>0.1</length>
              <radius>0.1</radius>
            </cylinder>
          </geometry>
        </visual>
        <self_collide>0</self_collide>
        <enable_wind>0</enable_wind>
        <kinematic>0</kinematic>
      </link>
      <joint name='front_right_wheel_joint' type='revolute'>
        <pose relative_to='front_right_suspension_link'>0 0 -0.202 0 -0 0</pose>
        <parent>front_right_suspension_link</parent>
        <child>front_right_wheel_link</child>
        <axis>
          <xyz>0 1 0</xyz>
          <limit>
            <lower>-1e+16</lower>
            <upper>1e+16</upper>
          </limit>
          <dynamics>
            <damping>10</damping>
            <friction>0</friction>
            <spring_reference>0</spring_reference>
            <spring_stiffness>0</spring_stiffness>
          </dynamics>
        </axis>
      </joint>
      <link name='front_right_wheel_link'>
        <pose relative_to='front_right_wheel_joint'>0 0 0 0 -0 0</pose>
        <inertial>
          <pose>0 0 0 0 -0 0</pose>
          <mass>0.5</mass>
          <inertia>
            <ixx>0.001</ixx>
            <ixy>0</ixy>
            <ixz>0</ixz>
            <iyy>0.001</iyy>
            <iyz>0</iyz>
            <izz>0.001</izz>
          </inertia>
        </inertial>
        <collision name='front_right_wheel_link_collision'>
          <pose>0 0 0 0 -0 0</pose>
          <geometry>
            <cylinder>
              <length>0.1</length>
              <radius>0.102</radius>
            </cylinder>
          </geometry>
          <surface>
            <contact>
              <ode>
                <kp>10000</kp>
                <kd>300</kd>
              </ode>
            </contact>
            <friction>
              <ode>
                <mu>0.6</mu>
                <mu2>0.6</mu2>
              </ode>
              <torsional>
                <ode/>
              </torsional>
            </friction>
            <bounce/>
          </surface>
          <max_contacts>10</max_contacts>
        </collision>
        <visual name='front_right_wheel_link_visual'>
          <pose>0 0 0 0 -0 0</pose>
          <geometry>
            <mesh>
              <scale>1 1 1</scale>
              <uri>/home/loookup/robotics/happy_robo/src/happy_robot/meshes/wheel.dae</uri>
            </mesh>
          </geometry>
          <material>
            <script>
              <name>Gazebo/Black</name>
              <uri>file://media/materials/scripts/gazebo.material</uri>
            </script>
          </material>
        </visual>
        <self_collide>0</self_collide>
        <enable_wind>0</enable_wind>
        <kinematic>0</kinematic>
      </link>
      <joint name='rear_left_steering_joint' type='revolute'>
        <pose relative_to='base_link'>-2.825 1.25 -0.1 0 -0 0</pose>
        <parent>base_link</parent>
        <child>rear_left_steering_link</child>
        <axis>
          <xyz>0 0 -1</xyz>
          <limit>
            <lower>-1e+16</lower>
            <upper>1e+16</upper>
          </limit>
          <dynamics>
            <damping>1</damping>
            <friction>0.5</friction>
            <spring_reference>0</spring_reference>
            <spring_stiffness>0</spring_stiffness>
          </dynamics>
        </axis>
      </joint>
      <link name='rear_left_steering_link'>
        <pose relative_to='rear_left_steering_joint'>0 0 0 0 -0 0</pose>
        <inertial>
          <pose>0 0 -0.133333 0 -0 0</pose>
          <mass>3</mass>
          <inertia>
            <ixx>0.369667</ixx>
            <ixy>0</ixy>
            <ixz>0</ixz>
            <iyy>0.369667</iyy>
            <iyz>0</iyz>
            <izz>0.03</izz>
          </inertia>
        </inertial>
        <collision name='rear_left_steering_link_collision'>
          <pose>0 0 0 0 -0 0</pose>
          <geometry>
            <cylinder>
              <length>0.2</length>
              <radius>0.15</radius>
            </cylinder>
          </geometry>
          <max_contacts>10</max_contacts>
          <surface>
            <contact>
              <ode/>
            </contact>
            <bounce/>
            <friction>
              <torsional>
                <ode/>
              </torsional>
              <ode/>
            </friction>
          </surface>
        </collision>
        <collision name='rear_left_steering_link_fixed_joint_lump__rear_left_pillar_link_collision_1'>
          <pose>0 0 -1.2 0 -0 0</pose>
          <geometry>
            <cylinder>
              <length>2</length>
              <radius>0.1</radius>
            </cylinder>
          </geometry>
          <surface>
            <contact>
              <ode/>
            </contact>
            <friction>
              <ode/>
              <torsional>
                <ode/>
              </torsional>
            </friction>
            <bounce/>
          </surface>
          <max_contacts>10</max_contacts>
        </collision>
        <visual name='rear_left_steering_link_visual'>
          <pose>0 0 0 0 -0 0</pose>
          <geometry>
            <cylinder>
              <length>0.2</length>
              <radius>0.15</radius>
            </cylinder>
          </geometry>
        </visual>
        <visual name='rear_left_steering_link_fixed_joint_lump__rear_left_pillar_link_visual_1'>
          <pose>0 0 -1.2 0 -0 0</pose>
          <geometry>
            <cylinder>
              <length>2</length>
              <radius>0.1</radius>
            </cylinder>
          </geometry>
          <material>
            <script>
              <name>Gazebo/White</name>
              <uri>file://media/materials/scripts/gazebo.material</uri>
            </script>
          </material>
        </visual>
        <self_collide>0</self_collide>
        <enable_wind>0</enable_wind>
        <kinematic>0</kinematic>
      </link>
      <joint name='rear_left_suspension_joint' type='prismatic'>
        <pose relative_to='rear_left_steering_link'>0 0 -2.2 0 -0 0</pose>
        <parent>rear_left_steering_link</parent>
        <child>rear_left_suspension_link</child>
        <axis>
          <xyz>0 0 1</xyz>
          <limit>
            <lower>-0.075</lower>
            <upper>0.075</upper>
            <effort>1000</effort>
            <velocity>1</velocity>
          </limit>
          <dynamics>
            <damping>15</damping>
            <friction>0.01</friction>
            <spring_reference>0</spring_reference>
            <spring_stiffness>800</spring_stiffness>
          </dynamics>
        </axis>
        <physics>
          <ode>
            <limit>
              <cfm>0</cfm>
              <erp>0.2</erp>
            </limit>
          </ode>
        </physics>
        <springDamping>80.0</springDamping>
      </joint>
      <link name='rear_left_suspension_link'>
        <pose relative_to='rear_left_suspension_joint'>0 0 0 0 -0 0</pose>
        <inertial>
          <pose>0 0 0 0 -0 0</pose>
          <mass>0.5</mass>
          <inertia>
            <ixx>0.005</ixx>
            <ixy>0</ixy>
            <ixz>0</ixz>
            <iyy>0.005</iyy>
            <iyz>0</iyz>
            <izz>0.005</izz>
          </inertia>
        </inertial>
        <collision name='rear_left_suspension_link_collision'>
          <pose>0 0 0 0 -0 0</pose>
          <geometry>
            <cylinder>
              <length>0.1</length>
              <radius>0.1</radius>
            </cylinder>
          </geometry>
          <max_contacts>10</max_contacts>
          <surface>
            <contact>
              <ode/>
            </contact>
            <bounce/>
            <friction>
              <torsional>
                <ode/>
              </torsional>
              <ode/>
            </friction>
          </surface>
        </collision>
        <visual name='rear_left_suspension_link_visual'>
          <pose>0 0 0 0 -0 0</pose>
          <geometry>
            <cylinder>
              <length>0.1</length>
              <radius>0.1</radius>
            </cylinder>
          </geometry>
        </visual>
        <self_collide>0</self_collide>
        <enable_wind>0</enable_wind>
        <kinematic>0</kinematic>
      </link>
      <joint name='rear_left_wheel_joint' type='revolute'>
        <pose relative_to='rear_left_suspension_link'>0 0 -0.202 0 -0 0</pose>
        <parent>rear_left_suspension_link</parent>
        <child>rear_left_wheel_link</child>
        <axis>
          <xyz>0 -1 0</xyz>
          <limit>
            <lower>-1e+16</lower>
            <upper>1e+16</upper>
          </limit>
          <dynamics>
            <damping>10</damping>
            <friction>0</friction>
            <spring_reference>0</spring_reference>
            <spring_stiffness>0</spring_stiffness>
          </dynamics>
        </axis>
      </joint>
      <link name='rear_left_wheel_link'>
        <pose relative_to='rear_left_wheel_joint'>0 0 0 0 -0 0</pose>
        <inertial>
          <pose>0 0 0 0 -0 0</pose>
          <mass>0.5</mass>
          <inertia>
            <ixx>0.001</ixx>
            <ixy>0</ixy>
            <ixz>0</ixz>
            <iyy>0.001</iyy>
            <iyz>0</iyz>
            <izz>0.001</izz>
          </inertia>
        </inertial>
        <collision name='rear_left_wheel_link_collision'>
          <pose>0 0 0 0 -0 0</pose>
          <geometry>
            <cylinder>
              <length>0.1</length>
              <radius>0.102</radius>
            </cylinder>
          </geometry>
          <surface>
            <contact>
              <ode>
                <kp>10000</kp>
                <kd>300</kd>
              </ode>
            </contact>
            <friction>
              <ode>
                <mu>0.6</mu>
                <mu2>0.6</mu2>
              </ode>
              <torsional>
                <ode/>
              </torsional>
            </friction>
            <bounce/>
          </surface>
          <max_contacts>10</max_contacts>
        </collision>
        <visual name='rear_left_wheel_link_visual'>
          <pose>0 0 0 0 -0 0</pose>
          <geometry>
            <mesh>
              <scale>1 1 1</scale>
              <uri>/home/loookup/robotics/happy_robo/src/happy_robot/meshes/wheel.dae</uri>
            </mesh>
          </geometry>
          <material>
            <script>
              <name>Gazebo/Black</name>
              <uri>file://media/materials/scripts/gazebo.material</uri>
            </script>
          </material>
        </visual>
        <self_collide>0</self_collide>
        <enable_wind>0</enable_wind>
        <kinematic>0</kinematic>
      </link>
      <joint name='rear_right_steering_joint' type='revolute'>
        <pose relative_to='base_link'>-2.825 -1.25 -0.1 0 -0 0</pose>
        <parent>base_link</parent>
        <child>rear_right_steering_link</child>
        <axis>
          <xyz>0 0 -1</xyz>
          <limit>
            <lower>-1e+16</lower>
            <upper>1e+16</upper>
          </limit>
          <dynamics>
            <damping>1</damping>
            <friction>0.5</friction>
            <spring_reference>0</spring_reference>
            <spring_stiffness>0</spring_stiffness>
          </dynamics>
        </axis>
      </joint>
      <link name='rear_right_steering_link'>
        <pose relative_to='rear_right_steering_joint'>0 0 0 0 -0 0</pose>
        <inertial>
          <pose>0 0 -0.133333 0 -0 0</pose>
          <mass>3</mass>
          <inertia>
            <ixx>0.369667</ixx>
            <ixy>0</ixy>
            <ixz>0</ixz>
            <iyy>0.369667</iyy>
            <iyz>0</iyz>
            <izz>0.03</izz>
          </inertia>
        </inertial>
        <collision name='rear_right_steering_link_collision'>
          <pose>0 0 0 0 -0 0</pose>
          <geometry>
            <cylinder>
              <length>0.2</length>
              <radius>0.15</radius>
            </cylinder>
          </geometry>
          <max_contacts>10</max_contacts>
          <surface>
            <contact>
              <ode/>
            </contact>
            <bounce/>
            <friction>
              <torsional>
                <ode/>
              </torsional>
              <ode/>
            </friction>
          </surface>
        </collision>
        <collision name='rear_right_steering_link_fixed_joint_lump__rear_right_pillar_link_collision_1'>
          <pose>0 0 -1.2 0 -0 0</pose>
          <geometry>
            <cylinder>
              <length>2</length>
              <radius>0.1</radius>
            </cylinder>
          </geometry>
          <surface>
            <contact>
              <ode/>
            </contact>
            <friction>
              <ode/>
              <torsional>
                <ode/>
              </torsional>
            </friction>
            <bounce/>
          </surface>
          <max_contacts>10</max_contacts>
        </collision>
        <visual name='rear_right_steering_link_visual'>
          <pose>0 0 0 0 -0 0</pose>
          <geometry>
            <cylinder>
              <length>0.2</length>
              <radius>0.15</radius>
            </cylinder>
          </geometry>
        </visual>
        <visual name='rear_right_steering_link_fixed_joint_lump__rear_right_pillar_link_visual_1'>
          <pose>0 0 -1.2 0 -0 0</pose>
          <geometry>
            <cylinder>
              <length>2</length>
              <radius>0.1</radius>
            </cylinder>
          </geometry>
          <material>
            <script>
              <name>Gazebo/White</name>
              <uri>file://media/materials/scripts/gazebo.material</uri>
            </script>
          </material>
        </visual>
        <self_collide>0</self_collide>
        <enable_wind>0</enable_wind>
        <kinematic>0</kinematic>
      </link>
      <joint name='rear_right_suspension_joint' type='prismatic'>
        <pose relative_to='rear_right_steering_link'>0 0 -2.2 0 -0 0</pose>
        <parent>rear_right_steering_link</parent>
        <child>rear_right_suspension_link</child>
        <axis>
          <xyz>0 0 1</xyz>
          <limit>
            <lower>-0.075</lower>
            <upper>0.075</upper>
            <effort>1000</effort>
            <velocity>1</velocity>
          </limit>
          <dynamics>
            <damping>15</damping>
            <friction>0.01</friction>
            <spring_reference>0</spring_reference>
            <spring_stiffness>800</spring_stiffness>
          </dynamics>
        </axis>
        <physics>
          <ode>
            <limit>
              <cfm>0</cfm>
              <erp>0.2</erp>
            </limit>
          </ode>
        </physics>
        <springDamping>80.0</springDamping>
      </joint>
      <link name='rear_right_suspension_link'>
        <pose relative_to='rear_right_suspension_joint'>0 0 0 0 -0 0</pose>
        <inertial>
          <pose>0 0 0 0 -0 0</pose>
          <mass>0.5</mass>
          <inertia>
            <ixx>0.005</ixx>
            <ixy>0</ixy>
            <ixz>0</ixz>
            <iyy>0.005</iyy>
            <iyz>0</iyz>
            <izz>0.005</izz>
          </inertia>
        </inertial>
        <collision name='rear_right_suspension_link_collision'>
          <pose>0 0 0 0 -0 0</pose>
          <geometry>
            <cylinder>
              <length>0.1</length>
              <radius>0.1</radius>
            </cylinder>
          </geometry>
          <max_contacts>10</max_contacts>
          <surface>
            <contact>
              <ode/>
            </contact>
            <bounce/>
            <friction>
              <torsional>
                <ode/>
              </torsional>
              <ode/>
            </friction>
          </surface>
        </collision>
        <visual name='rear_right_suspension_link_visual'>
          <pose>0 0 0 0 -0 0</pose>
          <geometry>
            <cylinder>
              <length>0.1</length>
              <radius>0.1</radius>
            </cylinder>
          </geometry>
        </visual>
        <self_collide>0</self_collide>
        <enable_wind>0</enable_wind>
        <kinematic>0</kinematic>
      </link>
      <joint name='rear_right_wheel_joint' type='revolute'>
        <pose relative_to='rear_right_suspension_link'>0 0 -0.202 0 -0 0</pose>
        <parent>rear_right_suspension_link</parent>
        <child>rear_right_wheel_link</child>
        <axis>
          <xyz>0 1 0</xyz>
          <limit>
            <lower>-1e+16</lower>
            <upper>1e+16</upper>
          </limit>
          <dynamics>
            <damping>10</damping>
            <friction>0</friction>
            <spring_reference>0</spring_reference>
            <spring_stiffness>0</spring_stiffness>
          </dynamics>
        </axis>
      </joint>
      <link name='rear_right_wheel_link'>
        <pose relative_to='rear_right_wheel_joint'>0 0 0 0 -0 0</pose>
        <inertial>
          <pose>0 0 0 0 -0 0</pose>
          <mass>0.5</mass>
          <inertia>
            <ixx>0.001</ixx>
            <ixy>0</ixy>
            <ixz>0</ixz>
            <iyy>0.001</iyy>
            <iyz>0</iyz>
            <izz>0.001</izz>
          </inertia>
        </inertial>
        <collision name='rear_right_wheel_link_collision'>
          <pose>0 0 0 0 -0 0</pose>
          <geometry>
            <cylinder>
              <length>0.1</length>
              <radius>0.102</radius>
            </cylinder>
          </geometry>
          <surface>
            <contact>
              <ode>
                <kp>10000</kp>
                <kd>300</kd>
              </ode>
            </contact>
            <friction>
              <ode>
                <mu>0.6</mu>
                <mu2>0.6</mu2>
              </ode>
              <torsional>
                <ode/>
              </torsional>
            </friction>
            <bounce/>
          </surface>
          <max_contacts>10</max_contacts>
        </collision>
        <visual name='rear_right_wheel_link_visual'>
          <pose>0 0 0 0 -0 0</pose>
          <geometry>
            <mesh>
              <scale>1 1 1</scale>
              <uri>/home/loookup/robotics/happy_robo/src/happy_robot/meshes/wheel.dae</uri>
            </mesh>
          </geometry>
          <material>
            <script>
              <name>Gazebo/Black</name>
              <uri>file://media/materials/scripts/gazebo.material</uri>
            </script>
          </material>
        </visual>
        <self_collide>0</self_collide>
        <enable_wind>0</enable_wind>
        <kinematic>0</kinematic>
      </link>
      <static>0</static>
      <plugin name='gazebo_ros_control' filename='libgazebo_ros_control.so'>
        <robotNamespace>/swerve_drive_robot</robotNamespace>
      </plugin>
      <pose>0 0 2.1 0 -0 0</pose>
    </model>
  </world>
</sdf>
